<?xml version="1.0"?>
<robot name="my_robot">
    <material name="green">
        <color rgba="0.0 0.6 0.0 1"/>
    </material>
    <material name="blue">
        <color rgba="0.0 0.0 1.0 1"/>
    </material>
    <material name="white">
        <color rgba="1 1 1 1"/>
    </material>

    <link name="base_footprint"/>

    <link name="base_link">
        <visual>
            <geometry>
                <box size="0.6 0.4 0.2"/>
            </geometry>
            <origin xyz="0.0 0.0 0.1" rpy="0 0 0"/>
            <material name="blue"/>
        </visual>
    </link>
    
    <link name="lidar">
        <visual>
            <geometry>
                <cylinder radius="0.1" length="0.05"/>
            </geometry>
            <origin xyz="0.0 0.0 0" rpy="0 0 0"/>
            <material name="white"/>
        </visual>
    </link>
    <link name="caster_wheel">
        <visual>
                <geometry>
                    <sphere radius="0.05"/>
                </geometry> 
            <origin xyz="0.0 0.0 0" rpy="0 0 0"/>
            <material name="white"/>
        </visual>
    </link>
    <link name="left_wheel">
        <visual>
            <geometry>
                <cylinder radius="0.1" length="0.05"/>
            </geometry>
            <origin xyz="0.0 0.0 0" rpy="1.57 0 0"/>
            <material name="white"/>
        </visual>
    </link>
    <gazebo reference="left_wheel">
        <kp>100000000000000000000.0</kp>
        <kd>100000000000000000000.0</kd>
        <mu1>10</mu1>
        <mu2>10</mu2>
        <material>Gazebo/Black</material>
    </gazebo>
    
    <link name="right_wheel">
        <visual>
            <geometry>
                <cylinder radius="0.1" length="0.05"/>
            </geometry>
            <origin xyz="0.0 0.0 0" rpy="1.57 0 0"/>
            <material name="white"/>
        </visual>
    </link>

    <gazebo reference="right_wheel">
        <kp>100000000000000000000.0</kp>
        <kd>100000000000000000000.0</kd>
        <mu1>10</mu1>
        <mu2>10</mu2>
        <material>Gazebo/Black</material>
    </gazebo>

    <joint name="base_joint" type="fixed">
        <parent link="base_footprint"/>
        <child link="base_link"/>
        <origin xyz="0.0 0.0 0.1" rpy="0 0 0"/>
    </joint>

    <joint name="base_lidar_joint" type="fixed">
        <parent link="base_link"/>
        <child link="lidar"/>
        <origin xyz="0.0 0.0 0.225" rpy="0 0 0"/>
    </joint>

    <joint name="left_wheel_joint" type="continuous">
        <parent link="base_link"/>
        <child link="left_wheel"/>
        <origin xyz="-0.15 -0.225 0.0" rpy="0 0 0"/>
        <axis xyz="0.0 1.0 0.0"/>
    </joint>

    <joint name="right_wheel_joint" type="continuous">
        <parent link="base_link"/>
        <child link="right_wheel"/>
        <origin xyz="-0.15 0.225 0.0" rpy="0 0 0"/>
        <axis xyz="0.0 1.0 0.0"/>
    </joint>

    <joint name="caster_wheel_joint" type="fixed">
        <parent link="base_link"/>
        <child link="caster_wheel"/>
        <origin xyz="0.2 0 -0.05" rpy="0 0 0"/>
    </joint>

    <!-- PLUGINS -->
    <!-- JOINT PUBLISHER -->
    <gazebo>
        <plugin name="bot_joint_state" filename="libgazebo_ros_joint_state_publisher.so">
            <ros>
                <remapping>~/out:=joint_states</remapping>
            </ros>
            <update_rate>30</update_rate>

            <joint_name>right_wheel_joint</joint_name>
            <joint_name>left_wheel_joint</joint_name>
            <joint_name>caster_wheel_joint</joint_name>
            <joint_name>base_lidar_joint</joint_name>
        </plugin>
    </gazebo>

    <gazebo>
        <plugin name="differential_drive_controller" filename="libgazebo_ros_diff_drive.so">

            <!-- Wheel Information -->
            <update_rate>30</update_rate>
            <left_joint>left_wheel_joint</left_joint>
            <right_joint>right_wheel_joint</right_joint>
            <wheel_separation>0.36</wheel_separation>
            <wheel_diameter>0.18</wheel_diameter>
            <!-- Limits -->
            <max_wheel_torque>1.0</max_wheel_torque>
            <max_wheel_acceleration>1.0</max_wheel_acceleration>
            <!-- Output -->
            <command_topic>cmd_vel</command_topic>
            <publish_odom>true</publish_odom>
            <publish_odom_tf>true</publish_odom_tf>
            <odometry_frame>odom</odometry_frame>
            <robot_base_frame>base_link</robot_base_frame>
            <publish_wheel_tf>true</publish_wheel_tf>
        </plugin>
    </gazebo>
</robot> 
